Traceback (most recent call last):
  File "/opt/anaconda3/lib/python3.7/site-packages/jupyter_cache/executors/utils.py", line 56, in single_nb_execution
    record_timing=False,
  File "/opt/anaconda3/lib/python3.7/site-packages/nbclient/client.py", line 1112, in execute
    return NotebookClient(nb=nb, resources=resources, km=km, **kwargs).execute()
  File "/opt/anaconda3/lib/python3.7/site-packages/nbclient/util.py", line 74, in wrapped
    return just_run(coro(*args, **kwargs))
  File "/opt/anaconda3/lib/python3.7/site-packages/nbclient/util.py", line 53, in just_run
    return loop.run_until_complete(coro)
  File "/opt/anaconda3/lib/python3.7/asyncio/base_events.py", line 579, in run_until_complete
    return future.result()
  File "/opt/anaconda3/lib/python3.7/site-packages/nbclient/client.py", line 554, in async_execute
    cell, index, execution_count=self.code_cells_executed + 1
  File "/opt/anaconda3/lib/python3.7/site-packages/nbclient/client.py", line 857, in async_execute_cell
    self._check_raise_for_error(cell, exec_reply)
  File "/opt/anaconda3/lib/python3.7/site-packages/nbclient/client.py", line 760, in _check_raise_for_error
    raise CellExecutionError.from_cell_and_msg(cell, exec_reply_content)
nbclient.exceptions.CellExecutionError: An error occurred while executing the following cell:
------------------
from obspy.io.segy.segy import _read_segy

stream = _read_segy('../data/3X_75_PR.SGY', headonly=True)
------------------

[0;31m---------------------------------------------------------------------------[0m
[0;31mFileNotFoundError[0m                         Traceback (most recent call last)
[0;32m<ipython-input-2-f22874b059ba>[0m in [0;36m<module>[0;34m[0m
[1;32m      1[0m [0;32mfrom[0m [0mobspy[0m[0;34m.[0m[0mio[0m[0;34m.[0m[0msegy[0m[0;34m.[0m[0msegy[0m [0;32mimport[0m [0m_read_segy[0m[0;34m[0m[0;34m[0m[0m
[1;32m      2[0m [0;34m[0m[0m
[0;32m----> 3[0;31m [0mstream[0m [0;34m=[0m [0m_read_segy[0m[0;34m([0m[0;34m'../data/3X_75_PR.SGY'[0m[0;34m,[0m [0mheadonly[0m[0;34m=[0m[0;32mTrue[0m[0;34m)[0m[0;34m[0m[0;34m[0m[0m
[0m
[0;32m/opt/anaconda3/lib/python3.7/site-packages/obspy/io/segy/segy.py[0m in [0;36m_read_segy[0;34m(file, endian, textual_header_encoding, unpack_headers, headonly)[0m
[1;32m    946[0m     [0;32mif[0m [0;32mnot[0m [0mhasattr[0m[0;34m([0m[0mfile[0m[0;34m,[0m [0;34m'read'[0m[0;34m)[0m [0;32mor[0m [0;32mnot[0m [0mhasattr[0m[0;34m([0m[0mfile[0m[0;34m,[0m [0;34m'tell'[0m[0;34m)[0m [0;32mor[0m [0;32mnot[0m[0;31m [0m[0;31m\[0m[0;34m[0m[0;34m[0m[0m
[1;32m    947[0m             [0mhasattr[0m[0;34m([0m[0mfile[0m[0;34m,[0m [0;34m'seek'[0m[0;34m)[0m[0;34m:[0m[0;34m[0m[0;34m[0m[0m
[0;32m--> 948[0;31m         [0;32mwith[0m [0mopen[0m[0;34m([0m[0mfile[0m[0;34m,[0m [0;34m'rb'[0m[0;34m)[0m [0;32mas[0m [0mopen_file[0m[0;34m:[0m[0;34m[0m[0;34m[0m[0m
[0m[1;32m    949[0m             return _internal_read_segy(
[1;32m    950[0m                 [0mopen_file[0m[0;34m,[0m [0mendian[0m[0;34m=[0m[0mendian[0m[0;34m,[0m[0;34m[0m[0;34m[0m[0m

[0;31mFileNotFoundError[0m: [Errno 2] No such file or directory: '../data/3X_75_PR.SGY'
FileNotFoundError: [Errno 2] No such file or directory: '../data/3X_75_PR.SGY'

